Workbook
Name Cfg_Empresa: 'CONFIGURACION'!$B$4
Name Cfg_CentroTecnico: 'CONFIGURACION'!$B$5
Name Cfg_NumCentro: 'CONFIGURACION'!$B$6
Name Cfg_Direccion1: 'CONFIGURACION'!$B$7
Name Cfg_Direccion2: 'CONFIGURACION'!$B$8
Name Cfg_Ciudad: 'CONFIGURACION'!$B$9
Name Cfg_CiudadFirma: 'CONFIGURACION'!$B$10
Name Cfg_Email: 'CONFIGURACION'!$B$11
Name Cfg_Destinatario: 'CONFIGURACION'!$B$12
Name Cfg_ResponsableTecnico: 'CONFIGURACION'!$B$15
Name Cfg_Elaborado: 'CONFIGURACION'!$B$16
Name Cfg_Aprobado: 'CONFIGURACION'!$B$17
Name Cfg_Version: 'CONFIGURACION'!$B$20
Name Cfg_FechaEdicion: 'CONFIGURACION'!$B$21
Name Cfg_CodJust: 'CONFIGURACION'!$B$22
Name Cfg_CodCliente: 'CONFIGURACION'!$B$23
Name Cfg_CodAdmin: 'CONFIGURACION'!$B$24
Name Cfg_CodRegistro: 'CONFIGURACION'!$B$25
Name Cfg_Conservacion: 'CONFIGURACION'!$B$26
Name Cfg_UrlTramite: 'CONFIGURACION'!$B$29
Name Cfg_UrlTramiteOVT: 'CONFIGURACION'!$B$30
Name Txt_J_Informado: 'CONFIGURACION'!$B$43
Name Txt_J_Contrasena: 'CONFIGURACION'!$B$44
Name Txt_J_Marca: 'CONFIGURACION'!$B$45
Name Txt_En: 'CONFIGURACION'!$B$46
Name Txt_A: 'CONFIGURACION'!$B$47
Name Txt_Sello: 'CONFIGURACION'!$B$48
Name Txt_Entrega_Si: 'CONFIGURACION'!$B$49
Name Txt_Achatarrar_Si: 'CONFIGURACION'!$B$50
Name Txt_Fitxer: 'CONFIGURACION'!$B$51
Name Txt_Confid: 'CONFIGURACION'!$B$52
Name Txt_Custodia: 'CONFIGURACION'!$B$53
Name Txt_Titularidad: 'CONFIGURACION'!$B$54
Name Txt_Cat_1: 'CONFIGURACION'!$B$55
Name Txt_Cat_2: 'CONFIGURACION'!$B$56
Name Txt_Cat_3: 'CONFIGURACION'!$B$57
Name Txt_Cat_4: 'CONFIGURACION'!$B$58
Name Txt_Cat_5: 'CONFIGURACION'!$B$59
Name Txt_Cat_6: 'CONFIGURACION'!$B$60
Name Dat_Empresa: 'DATOS'!$B$5
Name Dat_Nombre: 'DATOS'!$B$6
Name Dat_Nif: 'DATOS'!$B$7
Name Dat_DocTitularidad: 'DATOS'!$B$8
Name Dat_Matricula: 'DATOS'!$B$10
Name Dat_Bastidor: 'DATOS'!$B$11
Name Dat_Marca: 'DATOS'!$B$13
Name Dat_Modelo: 'DATOS'!$B$14
Name Dat_Serie: 'DATOS'!$B$15
Name Dat_NumInforme: 'DATOS'!$B$17
Name Dat_FechaInforme: 'DATOS'!$B$18
Name Dat_FechaEntrega: 'DATOS'!$B$19
Name Dat_TipoOperacion: 'DATOS'!$B$20
Name Dat_Tecnico: 'DATOS'!$B$21
Name Dat_FechaTransf: 'DATOS'!$B$23
Name Dat_FechaEnvio: 'DATOS'!$B$24
Name Dat_Modalidad: 'DATOS'!$B$26
Name Dat_NombreReceptor: 'DATOS'!$B$28
Name Dat_DniReceptor: 'DATOS'!$B$29
Name Dat_EntregaAparato: 'DATOS'!$B$31
Name Dat_Achatarrar: 'DATOS'!$B$32

Sheet DATOS
A1: DATOS DE LA INTERVENCIÓN
A2: Rellena sólo las celdas amarillas. Todos los documentos se generan desde aquí. | B2: =IF(SUM(D5:D32)=0,"✔ Datos completos","⚠ Faltan "&SUM(D5:D32)&" campo(s) obligatorio(s)")
A4: CLIENTE / EMPRESA DE TRANSPORTES
A5: Empresa | B5: COMERCIAL TANK FOODS S.L. | C5: =IF(B5="","⚠ Obligatorio","") | D5: =IF(C5<>"",1,0)
A6: Nombre de quien autoriza | B6: Joan Pla Serra | C6: =IF(B6="","⚠ Obligatorio","") | D6: =IF(C6<>"",1,0)
A7: DNI / NIF de quien autoriza | B7: 39887654T | C7: =IF(B7="","⚠ Obligatorio","") | D7: =IF(C7<>"",1,0)
A8: Documento de titularidad aportado | B8: Sí | C8: =IF(B8="","⚠ Obligatorio","") | D8: =IF(C8<>"",1,0)
A9: VEHÍCULO
A10: Matrícula | B10: 7567MPF | C10: =IF(B10="","⚠ Obligatorio","") | D10: =IF(C10<>"",1,0)
A11: Nº de bastidor | B11: VF3XXXXXXXXXXXXXX | C11: opcional | D11: 0
A12: TACÓGRAFO SUSTITUIDO (unidad intravehicular)
A13: Marca / fabricante | B13: VDO | C13: =IF(B13="","⚠ Obligatorio","") | D13: =IF(C13<>"",1,0)
A14: Modelo de la unidad | B14: 1381.7550303006 | C14: =IF(B14="","⚠ Obligatorio","") | D14: =IF(C14<>"",1,0)
A15: Nº de serie | B15: 1000567 | C15: =IF(B15="","⚠ Obligatorio","") | D15: =IF(C15<>"",1,0)
A16: INTERVENCIÓN
A17: Nº informe / certificado | B17: E943009003781L | C17: =IF(B17="","⚠ Obligatorio","") | D17: =IF(C17<>"",1,0)
A18: Fecha informe | B18: 2025-03-10 | C18: =IF(B18="","⚠ Obligatorio","") | D18: =IF(C18<>"",1,0)
A19: Fecha entrega al cliente | B19: 2025-03-14 | C19: =IF(AND($B$20="Intransferibilidad",B19=""),"⚠ Obligatorio","") | D19: =IF(C19<>"",1,0)
A20: Tipo de operación | B20: Intransferibilidad | C20: =IF(B20="","⚠ Obligatorio","") | D20: =IF(C20<>"",1,0)
A21: Técnico que interviene | B21: Marc Roig | C21: =IF(B21="","⚠ Obligatorio","") | D21: =IF(C21<>"",1,0)
A22: TRANSFERENCIA DE DATOS
A23: Fecha de transferencia | B23: 2025-03-10 | C23: =IF(AND($B$20="Transferencia correcta",B23=""),"⚠ Obligatorio","") | D23: =IF(C23<>"",1,0)
A24: Fecha de envío | B24: 2025-03-11 | C24: =IF(AND($B$20="Transferencia correcta",B24=""),"⚠ Obligatorio","") | D24: =IF(C24<>"",1,0)
A25: ENTREGA DE LOS DATOS DESCARGADOS
A26: Modalidad de entrega | B26: En mano | C26: =IF(AND($B$20="Transferencia correcta",B26=""),"⚠ Obligatorio","") | D26: =IF(C26<>"",1,0)
A27: PERSONA QUE RECIBE EL CERTIFICADO (acuse de intransferibilidad)
A28: Nombre de la persona receptora | B28: Marta Solé Vidal | C28: =IF(AND($B$20="Intransferibilidad",B28=""),"⚠ Obligatorio","") | D28: =IF(C28<>"",1,0)
A29: DNI de la persona receptora | B29: 40123456X | C29: =IF(AND($B$20="Intransferibilidad",B29=""),"⚠ Obligatorio","") | D29: =IF(C29<>"",1,0)
A30: TACÓGRAFO AVERIADO
A31: Se entrega al cliente | B31: No | C31: =IF(AND($B$20="Intransferibilidad",B31=""),"⚠ Obligatorio","") | D31: =IF(C31<>"",1,0)
A32: Se achatarrará (excluyente) | B32: =IF(B31="Sí","No",IF(B31="No","Sí","")) | C32: automático | D32: 0
A34: Destrucción de los archivos | B34: =IF(B23="","","Conservar hasta "&RIGHT("0"&DAY(EDATE(B23,12)),2)&"/"&RIGHT("0"&MONTH(EDATE(B23,12)),2)&"/"&YEAR(EDATE(B23,12))&" y destruir después (nota F, RD 125/2017)")

Sheet JUSTIFICANTE TRANSFERENCIA
B1: ='CONFIGURACION'!$B$4
B2: JUSTIFICANTE PARA AUTORIZAR TODO EL PROCESO DE TRANSFERENCIA, EN EL CAMBIO DE UN TACÓGRAFO DIGITAL CON DESCARGA DE LA MEMORIA INTERNA DEL MISMO.
B3: ="Yo, "&IF('DATOS'!$B$6="","",'DATOS'!$B$6)
B4: ="con N.I.F. nº: "&IF('DATOS'!$B$7="","",'DATOS'!$B$7)
B5: ="en representación de la empresa de transportes: "&IF('DATOS'!$B$5="","",'DATOS'!$B$5)
B6: ="propietaria del vehículo matrícula: "&UPPER(IF('DATOS'!$B$10="","",'DATOS'!$B$10))
B7: ='CONFIGURACION'!$B$43&'CONFIGURACION'!$B$4&","
B8: ='CONFIGURACION'!$B$44&'CONFIGURACION'!$B$6&'CONFIGURACION'!$B$45&" "&IF('DATOS'!$B$13="","",'DATOS'!$B$13)
B9: ="modelo: "&IF('DATOS'!$B$14="","",'DATOS'!$B$14)&" y número de serie: "&IF('DATOS'!$B$15="","",'DATOS'!$B$15)
B10: instalado en el vehículo de matrícula indicada arriba, que ha de cambiarse, puede ser correctamente descargado en el contenido de su memoria interna.
B11: Siendo representante de la empresa propietaria del vehículo o estando autorizado por la Dirección de la misma, doy la indicación y autorizo, al centro técnico de tacógrafos de COMERCIAL SEA, S.A. a la descarga de la mencionada memoria interna del tacógrafo.
B12: Quedo advertido, en caso de no ser uno de los representantes de dicha empresa, de que debo autorizar todo este proceso habiendo recibido indicación expresa de la Dirección de la misma a actuar en el sentido en el que me manifiesto y que el proceso no tendrá respaldo legal si yo falseo esta autorización.
B13: Doy la indicación, así mismo, de que los archivos de transferencia originados en la mencionada descarga sean entregados a la empresa propietaria del vehículo a través del medio indicado debajo, de entre las cuatro posibles opciones indicadas en el punto 6 de la disposición adicional primera del Real decreto 125/2017 (señálese la opción que proceda)
B14: Entrega en mano a una persona designada y autorizada para tal por la empresa propietaria del vehículo de matrícula arriba indicada | H14: =IF('DATOS'!$B$26="En mano","X","")
B15: Entrega por medios electrónicos (por ejemplo, email) | H15: =IF('DATOS'!$B$26="Email","X","")
B16: Entrega a través de empresa de mensajería | H16: =IF('DATOS'!$B$26="Mensajería","X","")
B17: Entrega por correo certificado | H17: =IF('DATOS'!$B$26="Correo certificado","X","")
B18: ='CONFIGURACION'!$B$52
B19: ='CONFIGURACION'!$B$53
B20: ='CONFIGURACION'!$B$54
B22: FIRMA DE LA PERSONA QUE AUTORIZA LA DESCARGA Y DA LA INDICACIÓN PARA LA MODALIDAD DE ENTREGA DE LOS ARCHIVOS DE TRANSFERENCIA
B23: ='CONFIGURACION'!$B$46&'CONFIGURACION'!$B$10&'CONFIGURACION'!$B$47&IF('DATOS'!$B$18="","",RIGHT("0"&DAY('DATOS'!$B$18),2)&"/"&RIGHT("0"&MONTH('DATOS'!$B$18),2)&"/"&YEAR('DATOS'!$B$18))
B24: =IF('DATOS'!$B$20="Transferencia correcta","","— NO APLICA: esta intervención está marcada como Intransferibilidad —")
B27: Persona que autoriza | F27: ="Técnico: "&IF('DATOS'!$B$21="","",'DATOS'!$B$21)
F28: ='CONFIGURACION'!$B$48&'CONFIGURACION'!$B$4
B30: ="Formato "&'CONFIGURACION'!$B$22&" · Versión "&'CONFIGURACION'!$B$20&" · Edición "&IF('CONFIGURACION'!$B$21="","",RIGHT("0"&DAY('CONFIGURACION'!$B$21),2)&"/"&RIGHT("0"&MONTH('CONFIGURACION'!$B$21),2)&"/"&YEAR('CONFIGURACION'!$B$21))&" · Elaborado: "&'CONFIGURACION'!$B$16&" · Aprobado: "&'CONFIGURACION'!$B$17&" · UNE 66102:2025"

Sheet INTRANSFERIBILIDAD CLIENTE
A1: ='CONFIGURACION'!$B$4
A2: ='CONFIGURACION'!$B$5
A3: ='CONFIGURACION'!$B$6
A4: ='CONFIGURACION'!$B$7
A5: ='CONFIGURACION'!$B$8
A6: ='CONFIGURACION'!$B$9
A9: Acuse de recibo Certificado de Intransferibilidad de datos
A11: =IF('DATOS'!$B$5="","",'DATOS'!$B$5)
A14: Estimados señores:
A16: En cumplimiento del requisito expresado en la disposición adicional primera, apartado 10, del Real decreto 125/2017, les remitimos copia del certificado de intransferibilidad correspondiente a la sustitución del tacógrafo:
A20: Modelo: | C20: =IF('DATOS'!$B$14="","",'DATOS'!$B$14)
A21: Nº de Serie: | C21: =IF('DATOS'!$B$15="","",'DATOS'!$B$15)
A23: Montado en el vehículo: | C23: =UPPER(IF('DATOS'!$B$10="","",'DATOS'!$B$10))
A24: Nº de informe/Certificado: | C24: =IF('DATOS'!$B$17="","",'DATOS'!$B$17)
A25: Fecha Informe: | C25: =IF('DATOS'!$B$18="","",'DATOS'!$B$18)
A27: Nombre: | C27: =IF('DATOS'!$B$28="","",'DATOS'!$B$28)
A28: DNI: | C28: =IF('DATOS'!$B$29="","",'DATOS'!$B$29)
A30: ="En calidad de personal/propietario de la organización de transportes propietaria del vehículo con matrícula "&UPPER(IF('DATOS'!$B$10="","",'DATOS'!$B$10))&" declaro haber recibido el certificado de intransferibilidad de fecha "&IF('DATOS'!$B$18="","",RIGHT("0"&DAY('DATOS'!$B$18),2)&"/"&RIGHT("0"&MONTH('DATOS'!$B$18),2)&"/"&YEAR('DATOS'!$B$18))&" correspondiente a la intervención técnica realizada sobre el vehículo de matrícula antedicha."
A34: En el caso de que el receptor no sea propietario de la organización de transportes, se compromete explícitamente, por el presente compromiso firmado, a entregar este documento (el certificado de intransferibilidad) a la propiedad de la citada organización
A38: =IF('DATOS'!$B$31="Sí",'CONFIGURACION'!$B$49,"")
A39: =IF('DATOS'!$B$32="Sí",'CONFIGURACION'!$B$50,"")
A41: ='CONFIGURACION'!$B$52
A44: Entregado
A45: ='CONFIGURACION'!$B$10&" a" | C45: =IF('DATOS'!$B$19="","",'DATOS'!$B$19)
A47: Firma:
A50: =IF('DATOS'!$B$20="Intransferibilidad","","— NO APLICA: esta intervención está marcada como Transferencia correcta —")
A52: ="Formato "&'CONFIGURACION'!$B$23&" · Versión "&'CONFIGURACION'!$B$20&" · Edición "&IF('CONFIGURACION'!$B$21="","",RIGHT("0"&DAY('CONFIGURACION'!$B$21),2)&"/"&RIGHT("0"&MONTH('CONFIGURACION'!$B$21),2)&"/"&YEAR('CONFIGURACION'!$B$21))&" · Elaborado: "&'CONFIGURACION'!$B$16&" · Aprobado: "&'CONFIGURACION'!$B$17&" · UNE 66102:2025"

Sheet INTRANSF. ADMINISTRACION
A1: ='CONFIGURACION'!$B$4
A2: ='CONFIGURACION'!$B$5
A3: ='CONFIGURACION'!$B$6
A4: ='CONFIGURACION'!$B$7
A5: ='CONFIGURACION'!$B$8
A6: ='CONFIGURACION'!$B$9
A9: Acuse de recibo Certificado de Intransferibilidad de datos
A11: ='CONFIGURACION'!$B$12
A14: Estimados señores:
A16: En cumplimiento del requisito expresado en la disposición adicional primera, apartado 10, del Real decreto 125/2017, les remitimos copia del certificado de intransferibilidad correspondiente a la sustitución del tacógrafo:
A20: Modelo: | C20: =IF('DATOS'!$B$14="","",'DATOS'!$B$14)
A21: Nº de Serie: | C21: =IF('DATOS'!$B$15="","",'DATOS'!$B$15)
A23: Montado en el vehículo: | C23: =UPPER(IF('DATOS'!$B$10="","",'DATOS'!$B$10))
A24: Nº de informe/Certificado: | C24: =IF('DATOS'!$B$17="","",'DATOS'!$B$17)
A25: Fecha Informe: | C25: =IF('DATOS'!$B$18="","",'DATOS'!$B$18)
A28: Entregado
A29: ='CONFIGURACION'!$B$10&" a" | C29: =IF('DATOS'!$B$19="","",'DATOS'!$B$19)
A32: =IF('DATOS'!$B$20="Intransferibilidad","","— NO APLICA: esta intervención está marcada como Transferencia correcta —")
A34: ="Formato "&'CONFIGURACION'!$B$24&" · Versión "&'CONFIGURACION'!$B$20&" · Edición "&IF('CONFIGURACION'!$B$21="","",RIGHT("0"&DAY('CONFIGURACION'!$B$21),2)&"/"&RIGHT("0"&MONTH('CONFIGURACION'!$B$21),2)&"/"&YEAR('CONFIGURACION'!$B$21))&" · Elaborado: "&'CONFIGURACION'!$B$16&" · Aprobado: "&'CONFIGURACION'!$B$17&" · UNE 66102:2025"
A38: TEXTO PARA EL TRÁMITE TELEMÁTICO DE LA GENERALITAT (no se imprime)
A40: Assumpte: | C40: Certificat de Intransferibilitat de dades Tacògraf digital
A41: Nom del fitxer: | C41: =IF('DATOS'!$B$17="","",'DATOS'!$B$17)&'CONFIGURACION'!$B$51
A43: Exposo / Sol·licito:
A44: Copiar esta celda y pegarla en el formulario del trámite.
A45: ='CONFIGURACION'!$B$55&IF('DATOS'!$B$14="","",'DATOS'!$B$14)&'CONFIGURACION'!$B$56&IF('DATOS'!$B$15="","",'DATOS'!$B$15)&'CONFIGURACION'!$B$57&UPPER(IF('DATOS'!$B$10="","",'DATOS'!$B$10))&'CONFIGURACION'!$B$58&IF('DATOS'!$B$17="","",'DATOS'!$B$17)&'CONFIGURACION'!$B$59&IF('DATOS'!$B$18="","",RIGHT("0"&DAY('DATOS'!$B$18),2)&"/"&RIGHT("0"&MONTH('DATOS'!$B$18),2)&"/"&YEAR('DATOS'!$B$18))&'CONFIGURACION'!$B$60
A51: Enlace al trámite: | C51: =HYPERLINK('CONFIGURACION'!$B$29,"Petició genèrica — gencat.cat")
A52: Formulario directo (OVT): | C52: =HYPERLINK('CONFIGURACION'!$B$30,"Obrir el formulari a l’OVT")
A53: Email del centro: | C53: ='CONFIGURACION'!$B$11

Sheet REGISTRO TRANSFERENCIAS
A1: REGISTRO DE TRANSFERENCIAS Y DE DESTRUCCIÓN DE ARCHIVOS
A2: UNE 66102:2025, 7.5.1 d) y 8.5.1 — registro de transferencias realizadas y documento de destrucción al año. La fila 5 se rellena sola con la intervención en curso; cópiala como valores a la primera fila libre al cerrar cada expediente.
A4: Nº informe | B4: Fecha transferencia | C4: Matrícula | D4: Nº bastidor | E4: Nº serie UIV | F4: Empresa | G4: Técnico | H4: Modalidad entrega | I4: Fecha envío | J4: Destruir a partir de | K4: Fecha destrucción | L4: Método de destrucción | M4: Persona que destruye | N4: Firma digital del archivo (hash) | O4: Estado
A5: =IF('DATOS'!$B$17="","",'DATOS'!$B$17) | B5: =IF('DATOS'!$B$23="","",'DATOS'!$B$23) | C5: =UPPER(IF('DATOS'!$B$10="","",'DATOS'!$B$10)) | D5: =IF('DATOS'!$B$11="","",'DATOS'!$B$11) | E5: =IF('DATOS'!$B$15="","",'DATOS'!$B$15) | F5: =IF('DATOS'!$B$5="","",'DATOS'!$B$5) | G5: =IF('DATOS'!$B$21="","",'DATOS'!$B$21) | H5: =IF('DATOS'!$B$26="","",'DATOS'!$B$26) | I5: =IF('DATOS'!$B$24="","",'DATOS'!$B$24) | J5: =IF('DATOS'!$B$23="","",EDATE('DATOS'!$B$23,12)) | O5: ← intervención en curso (automática)
J6: =IF(B6="","",EDATE(B6,12)) | O6: =IF(B6="","",IF(K6<>"","Destruido",IF(TODAY()>EDATE(B6,12),"⚠ PENDIENTE DE DESTRUIR","En custodia")))
J7: =IF(B7="","",EDATE(B7,12)) | O7: =IF(B7="","",IF(K7<>"","Destruido",IF(TODAY()>EDATE(B7,12),"⚠ PENDIENTE DE DESTRUIR","En custodia")))
J8: =IF(B8="","",EDATE(B8,12)) | O8: =IF(B8="","",IF(K8<>"","Destruido",IF(TODAY()>EDATE(B8,12),"⚠ PENDIENTE DE DESTRUIR","En custodia")))
J9: =IF(B9="","",EDATE(B9,12)) | O9: =IF(B9="","",IF(K9<>"","Destruido",IF(TODAY()>EDATE(B9,12),"⚠ PENDIENTE DE DESTRUIR","En custodia")))
J10: =IF(B10="","",EDATE(B10,12)) | O10: =IF(B10="","",IF(K10<>"","Destruido",IF(TODAY()>EDATE(B10,12),"⚠ PENDIENTE DE DESTRUIR","En custodia")))
J11: =IF(B11="","",EDATE(B11,12)) | O11: =IF(B11="","",IF(K11<>"","Destruido",IF(TODAY()>EDATE(B11,12),"⚠ PENDIENTE DE DESTRUIR","En custodia")))
J12: =IF(B12="","",EDATE(B12,12)) | O12: =IF(B12="","",IF(K12<>"","Destruido",IF(TODAY()>EDATE(B12,12),"⚠ PENDIENTE DE DESTRUIR","En custodia")))
J13: =IF(B13="","",EDATE(B13,12)) | O13: =IF(B13="","",IF(K13<>"","Destruido",IF(TODAY()>EDATE(B13,12),"⚠ PENDIENTE DE DESTRUIR","En custodia")))
J14: =IF(B14="","",EDATE(B14,12)) | O14: =IF(B14="","",IF(K14<>"","Destruido",IF(TODAY()>EDATE(B14,12),"⚠ PENDIENTE DE DESTRUIR","En custodia")))
J15: =IF(B15="","",EDATE(B15,12)) | O15: =IF(B15="","",IF(K15<>"","Destruido",IF(TODAY()>EDATE(B15,12),"⚠ PENDIENTE DE DESTRUIR","En custodia")))
J16: =IF(B16="","",EDATE(B16,12)) | O16: =IF(B16="","",IF(K16<>"","Destruido",IF(TODAY()>EDATE(B16,12),"⚠ PENDIENTE DE DESTRUIR","En custodia")))
J17: =IF(B17="","",EDATE(B17,12)) | O17: =IF(B17="","",IF(K17<>"","Destruido",IF(TODAY()>EDATE(B17,12),"⚠ PENDIENTE DE DESTRUIR","En custodia")))
... J39: =IF(B39="","",EDATE(B39,12)) | O39: =IF(B39="","",IF(K39<>"","Destruido",IF(TODAY()>EDATE(B39,12),"⚠ PENDIENTE DE DESTRUIR","En custodia")))

Sheet CONFIGURACION
A1: CONFIGURACIÓN DEL CENTRO TÉCNICO
A2: Datos que no cambian. Se escriben aquí una vez; los documentos los toman de estas celdas.
A3: IDENTIFICACIÓN DEL CENTRO
A4: Empresa | B4: COMERCIAL SEA S.A.
A5: Centro técnico | B5: Centro técnico de Tacógrafos
A6: Contraseña / nº de centro | B6: E943009
A7: Dirección (línea 1) | B7: Pol.Ind. Riu Clar
A8: Dirección (línea 2) | B8: C/ Coure, 27
A9: Código postal y ciudad | B9: 43006 Tarragona
A10: Ciudad de firma | B10: Tarragona
A11: Email del centro | B11: jcruset@comercialsea.es
A12: Destinatario administración | B12: Direcció General de Transports i Mobilitat
A14: RESPONSABLES (UNE 66102:2025, 7.5.2 y anexo C)
A15: Responsable técnico | B15: Jordi Cruset
A16: Documentación elaborada por | B16: Jordi Cruset
A17: Documentación aprobada por | B17: Dirección
A19: CONTROL DOCUMENTAL (UNE 66102:2025, 7.5.2 y 7.5.3)
A20: Versión del formato | B20: 02
A21: Fecha de edición del formato | B21: 2026-08-22
A22: Código formato — justificante transferencia | B22: CTT-F-01
A23: Código formato — acuse intransferibilidad | B23: CTT-F-03
A24: Código formato — comunicación administración | B24: CTT-F-04
A25: Código formato — registro de transferencias | B25: CTT-R-01
A26: Conservación de los archivos transferidos | B26: 1 año desde la transferencia (RD 125/2017, nota F)
A28: ENLACES
A29: Trámite Generalitat (petició genèrica) | B29: https://web.gencat.cat/ca/tramits/tramits-temes/Peticio-generica
A30: Trámite Generalitat (formulario OVT) | B30: https://ovt.gencat.cat/gsitgf/AppJava/traint/renderitzar.do?reqCode=inicial&set-locale=ca_ES&idioma=ca_ES&idServei=ING001SOLC&urlRetorn=https%3A%2F%2Fweb.gencat.cat%2Fca%2Ftramits%2Ftramits-temes%2FPeticio-generica%3Fmoda%3D1&tpst=ae56fd5821cffc7f4784ac8db0c0e1a0
A32: LISTAS
A33: Transferencia correcta
A34: Intransferibilidad
B35: En mano
B36: Email
B37: Mensajería
B38: Correo certificado
C39: Sí
C40: No
A42: FRAGMENTOS DE TEXTO LEGAL (editar sólo ante cambio normativo)
A43: Txt_J_Informado | B43: He sido informado por el centro técnico de tacógrafos de
A44: Txt_J_Contrasena | B44: con contraseña
A45: Txt_J_Marca | B45: , de que el tacógrafo marca:
...
